Workbook

Sheet Host
A1: Coevolution | M1: Host evolution
C2: 15 | F2: 20 | I2: 26 | O2: 15 | R2: 20 | U2: 26
C3: A | D3: B | E3: C | F3: A | G3: B | H3: C | I3: A | J3: B | K3: C | O3: A | P3: B | Q3: C | R3: A | S3: B | T3: C | U3: A | V3: B | W3: C
A4: g1 | B4: Cytometry (cells/mL) | C4: 3574.1479 | D4: 7473.2184 | E4: 15596.282 | F4: 28784587 | G4: 40519574 | H4: 36005329 | I4: 49754553 | J4: 51659034 | K4: 52489518 | M4: g6 | N4: Cytometry (cells/mL) | R4: 1.2601663e+08 | S4: 1.0391185e+08 | T4: 70161848
B5: Volume (μL) | C5: 50 | D5: 50 | E5: 50 | F5: 80 | G5: 80 | H5: 80 | I5: 80 | J5: 80 | K5: 80 | N5: Volume (μL) | R5: 50 | S5: 50 | T5: 50
B6: Qubit (ng/μL) | C6: 102 | D6: 67.4 | E6: 56.4 | F6: >120 | G6: >120 | H6: >120 | I6: >120 | J6: >120 | K6: >120 | N6: Qubit (ng/μL) | R6: >120 | S6: >120 | T6: >120
B7: Remarque | I7: Pb annot tube Lucien : même date que 26 g2 | N7: Remarque
A8: g2 | B8: Cytometry (cells/mL) | F8: 57372643 | G8: 71440511 | H8: 38498833 | I8: 40149783 | J8: 35415866 | K8: 41323225 | M8: g7 | N8: Cytometry (cells/mL) | O8: 4006103.8 | P8: 3571281 | Q8: 3555034.9 | R8: 73608335 | S8: 62715784 | T8: 46670345 | U8: 43816657 | V8: 38658940 | W8: 29350718
B9: Volume (μL) | F9: 80 | G9: 80 | H9: 80 | I9: 80 | J9: 80 | K9: 80 | N9: Volume (μL) | O9: 50 | P9: 50 | Q9: 50 | R9: 50 | S9: 50 | T9: 50 | U9: 50 | V9: 50 | W9: 50
B10: Qubit (ng/μL) | F10: >120 | G10: >120 | H10: >120 | I10: >120 | J10: >120 | K10: >120 | N10: Qubit (ng/μL) | O10: >120 | P10: >120 | Q10: >120 | R10: 2.74 | S10: 0.272 | T10: >120 | U10: >120 | V10: >120 | W10: >120
B11: Remarque | G11: Pb annot tube : peut-être échange avec 20C g2 | N11: Remarque | R11: Perte culots lors extraction
A12: g3 | B12: Cytometry (cells/mL) | F12: 30740228 | G12: 21085135 | H12: 36682277 | I12: 40799344 | J12: 45923345 | K12: 49686411
B13: Volume (μL) | F13: 80 | G13: 80 | H13: 80 | I13: 80 | J13: 80 | K13: 80
B14: Qubit (ng/μL) | F14: >120 | G14: >120 | H14: >120 | I14: >120 | J14: >120 | K14: >120
B15: Remarque
A16: g4 | B16: Cytometry (cells/mL) | F16: 55405761 | G16: 61970870 | H16: 63508696 | I16: 63460775 | J16: 51546983 | K16: 63303895
B17: Volume (μL) | F17: 80 | G17: 80 | H17: 80 | I17: 80 | J17: 80 | K17: 80
B18: Qubit (ng/μL) | F18: >120 | G18: >120 | H18: >120 | I18: >120 | J18: >120 | K18: >120
B19: Remarque
A20: g5 | B20: Cytometry (cells/mL) | F20: 37771290 | G20: 45378300 | H20: 40320976 | I20: 33969730 | J20: 33859656 | K20: 28925967
B21: Volume (μL) | F21: 80 | G21: 80 | H21: 80 | I21: 80 | J21: 80 | K21: 80
B22: Qubit (ng/μL) | F22: >120 | G22: >120 | H22: >120 | I22: >120 | J22: >120 | K22: >120
B23: Remarque

Sheet Virus
B2: Coevolution | N2: Virus evolution
D3: 15 | G3: 20 | J3: 26 | P3: 15 | S3: 20 | V3: 26
D4: A | E4: B | F4: C | G4: A | H4: B | I4: C | J4: A | K4: B | L4: C | P4: A | Q4: B | R4: C | S4: A | T4: B | U4: C | V4: A | W4: B | X4: C
B5: g1 | C5: Cytometry (parts/mL) | D5: 53285004 | E5: 53783197 | F5: 66324667 | G5: 4.7166931e+08 | H5: 5.0268931e+08 | I5: 4.2883448e+08 | J5: 3045267.9 | K5: 5108378.8 | L5: 4957277.7 | N5: g1 | O5: Cytometry (parts/mL) | P5: 48267887 | Q5: 62537958 | R5: 61035845 | S5: 3.3346901e+08 | T5: 4.0316704e+08 | U5: 2.8860592e+08 | V5: 4141307.4 | W5: 3758412.8 | X5: 5033048.7
C6: Videodrop avant (parts/mL) | D6: 47900000 | E6: 56400000 | F6: 73700000 | G6: 411000000 | H6: 457000000 | I6: 361000000 | J6: 1920000000 | K6: 1980000000 | L6: 2890000000 | O6: Videodrop avant (parts/mL) | P6: 72700000 | Q6: 58000000 | R6: 42600000 | S6: 184000000 | T6: 144000000 | U6: 219000000 | V6: 470000000 | W6: 487000000 | X6: 512000000 | Z6: =1900000000-49200000 -> 1850800000
C7: Videodrop avant/cyto (%) | D7: =D6/D5*100 -> 89.89396 | E7: =E6/E5*100 -> 104.86547 | F7: =F6/F5*100 -> 111.12005 | G7: =G6/G5*100 -> 87.137321 | H7: =H6/H5*100 -> 90.911024 | I7: =I6/I5*100 -> 84.181663 | J7: =J6/J5*100 -> 63048.64 | K7: =K6/K5*100 -> 38759.851 | L7: =L6/L5*100 -> 58298.126 | O7: Videodrop avant/cyto (%) | P7: =P6/P5*100 -> 150.61774 | Q7: =Q6/Q5*100 -> 92.743675 | R7: =R6/R5*100 -> 69.795052 | S7: =S6/S5*100 -> 55.17754 | T7: =T6/T5*100 -> 35.717205 | U7: =U6/U5*100 -> 75.882021 | V7: =V6/V5*100 -> 11349.073 | W7: =W6/W5*100 -> 12957.598 | X7: =X6/X5*100 -> 10172.761 | Z7: =410000000-37400000 -> 372600000
C8: Nouveau cyto | I8: 186000000 | L8: 289000
C9: nouveau cyto/cyto | I9: =I8/I5*100 -> 43.373378 | L9: =L8/L5*100 -> 5.8298126
C10: decay (d-1) | I10: =(log(I5)-log(I8))/711 -> 0.00051023454 | L10: =(log(L5)-log(L8))/727 -> 0.0016978616
C11: Videodrop après (parts/mL) | D11: 5530000000 | E11: 8460000000 | F11: 6390000000 | G11: 22800000000 | H11: 17300000000 | I11: 14700000000 | J11: 228000000000 | K11: 272000000000 | L11: 254000000000 | O11: Videodrop après (parts/mL) | P11: 3850000000 | Q11: 5250000000 | R11: 5780000000 | S11: 23000000000 | T11: 21900000000 | U11: 11600000000 | V11: 14100000000 | W11: 13400000000 | X11: 16800000000
C12: Videodrop après/cyto (%) | D12: =(D11*0.2)/(D5*40)*100 -> 51.890772 | E12: =(E11*0.2)/(E5*40)*100 -> 78.6491 | F12: =(F11*0.2)/(F5*40)*100 -> 48.172123 | G12: =(G11*0.2)/(G5*40)*100 -> 24.169476 | H12: =(H11*0.2)/(H5*40)*100 -> 17.207448 | I12: =(I11*0.2)/(I5*40)*100 -> 17.13948 | J12: =(J11*0.2)/(J5*40)*100 -> 37435.13 | K12: =(K11*0.2)/(K5*40)*100 -> 26622.928 | L12: =(L11*0.2)/(L5*40)*100 -> 25618.9 | O12: Videodrop après/cyto (%) | P12: =(P11*0.2)/(P5*40)*100 -> 39.881588 | Q12: =(Q11*0.2)/(Q5*40)*100 -> 41.974508 | R12: =(R11*0.2)/(R5*40)*100 -> 47.349226 | S12: =(S11*0.2)/(S5*40)*100 -> 34.485963 | T12: =(T11*0.2)/(T5*40)*100 -> 27.159958 | U12: =(U11*0.2)/(U5*40)*100 -> 20.096608 | V12: =(V11*0.2)/(V5*40)*100 -> 1702.361 | W12: =(W11*0.2)/(W5*40)*100 -> 1782.6674 | X12: =(X11*0.2)/(X5*40)*100 -> 1668.9685
C13: Videodrop après/avant (%) | D13: =(D11*0.2)/(D6*40)*100 -> 57.724426 | E13: =(E11*0.2)/(E6*40)*100 -> 75 | F13: =(F11*0.2)/(F6*40)*100 -> 43.351425 | G13: =(G11*0.2)/(G6*40)*100 -> 27.737226 | H13: =(H11*0.2)/(H6*40)*100 -> 18.92779 | I13: =(I11*0.2)/(I6*40)*100 -> 20.360111 | J13: =(J11*0.2)/(J6*40)*100 -> 59.375 | K13: =(K11*0.2)/(K6*40)*100 -> 68.686869 | L13: =(L11*0.2)/(L6*40)*100 -> 43.944637 | O13: Videodrop après/avant (%) | P13: =(P11*0.2)/(P6*40)*100 -> 26.478679 | Q13: =(Q11*0.2)/(Q6*40)*100 -> 45.258621 | R13: =(R11*0.2)/(R6*40)*100 -> 67.840376 | S13: =(S11*0.2)/(S6*40)*100 -> 62.5 | T13: =(T11*0.2)/(T6*40)*100 -> 76.041667 | U13: =(U11*0.2)/(U6*40)*100 -> 26.484018 | V13: =(V11*0.2)/(V6*40)*100 -> 15 | W13: =(W11*0.2)/(W6*40)*100 -> 13.7577 | X13: =(X11*0.2)/(X6*40)*100 -> 16.40625
C14: Volume (μL) | D14: 30 | E14: 30 | F14: 30 | G14: 40 | H14: 40 | I14: 40 | J14: 40 | K14: 40 | L14: 40 | O14: Volume (μL) | P14: 30 | Q14: 30 | R14: 30 | S14: 30 | T14: 30 | U14: 30 | V14: 30 | W14: 30 | X14: 30
C15: Qubit (ng/μL) | D15: 1.92 | E15: 6.72 | F15: 2.52 | G15: 26.4 | H15: 10.7 | I15: 63.6 | J15: 52.4 | K15: 156 | L15: 8.62 | O15: Qubit (ng/μL) | P15: 0.956 | Q15: 3.86 | R15: 5.64 | S15: 8.24 | T15: 4.1 | U15: 14.4 | V15: 4.62 | W15: 15.4 | X15: 2.64
C16: Masse ADN (ng) | D16: =D15*D14 -> 57.6 | E16: =E15*E14 -> 201.6 | F16: =F15*F14 -> 75.6 | G16: =G15*G14 -> 1056 | H16: =H15*H14 -> 428 | I16: =I15*I14 -> 2544 | J16: =J15*J14 -> 2096 | K16: =K15*K14 -> 6240 | L16: =L15*L14 -> 344.8 | O16: Masse ADN (ng) | P16: =P15*P14 -> 28.68 | Q16: =Q15*Q14 -> 115.8 | R16: =R15*R14 -> 169.2 | S16: =S15*S14 -> 247.2 | T16: =T15*T14 -> 123 | U16: =U15*U14 -> 432 | V16: =V15*V14 -> 138.6 | W16: =W15*W14 -> 462 | X16: =X15*X14 -> 79.2
D17: =D16/D11 -> 1.0415913e-08 | E17: =E16/E11 -> 2.3829787e-08 | F17: =F16/F11 -> 1.1830986e-08 | G17: =G16/G11 -> 4.6315789e-08 | H17: =H16/H11 -> 2.4739884e-08 | I17: =I16/I11 -> 1.7306122e-07 | J17: =J16/J11 -> 9.1929825e-09 | K17: =K16/K11 -> 2.2941176e-08 | L17: =L16/L11 -> 1.3574803e-09 | P17: =P16/P11 -> 7.4493506e-09 | Q17: =Q16/Q11 -> 2.2057143e-08 | R17: =R16/R11 -> 2.9273356e-08 | S17: =S16/S11 -> 1.0747826e-08 | T17: =T16/T11 -> 5.6164384e-09 | U17: =U16/U11 -> 3.7241379e-08 | V17: =V16/V11 -> 9.8297872e-09 | W17: =W16/W11 -> 3.4477612e-08 | X17: =X16/X11 -> 4.7142857e-09
C18: ADN/cyto (1E-9 ng.mL/parts) | D18: =D16/(D5*40)*1000000000 -> 27.024489 | E18: =E16/(E5*40)*1000000000 -> 93.709565 | F18: =F16/(F5*40)*1000000000 -> 28.496185 | G18: =G16/(G5*40)*1000000000 -> 55.971418 | H18: =H16/(H5*40)*1000000000 -> 21.285513 | I18: =I16/(I5*40)*1000000000 -> 148.30897 | J18: =J16/(J5*40)*1000000000 -> 17207.025 | K18: =K16/(K5*40)*1000000000 -> 30538.064 | L18: =L16/(L5*40)*1000000000 -> 1738.8576 | O18: ADN/cyto (1E-9 ng.mL/parts) | P18: =P16/(P5*40)*1000000000 -> 14.854597 | Q18: =Q16/(Q5*40)*1000000000 -> 46.291886 | R18: =R16/(R5*40)*1000000000 -> 69.303538 | S18: =S16/(S5*40)*1000000000 -> 18.532457 | T18: =T16/(T5*40)*1000000000 -> 7.6271115 | U18: =U16/(U5*40)*1000000000 -> 37.42127 | V18: =V16/(V5*40)*1000000000 -> 836.69231 | W18: =W16/(W5*40)*1000000000 -> 3073.1058 | X18: =X16/(X5*40)*1000000000 -> 393.39973
C19: ADN/Videodrop avant (1E-9 ng.mL/parts) | D19: =D16/(D6*40)*1000000000 -> 30.06263 | E19: =E16/(E6*40)*1000000000 -> 89.361702 | F19: =F16/(F6*40)*1000000000 -> 25.644505 | G19: =G16/(G6*40)*1000000000 -> 64.233577 | H19: vv | I19: =I16/(I6*40)*1000000000 -> 176.17729 | J19: =J16/(J6*40)*1000000000 -> 27.291667 | K19: =K16/(K6*40)*1000000000 -> 78.787879 | L19: =L16/(L6*40)*1000000000 -> 2.982699 | O19: ADN/Videodrop avant (1E-9 ng.mL/parts) | P19: =P16/(P6*40)*1000000000 -> 9.8624484 | Q19: =Q16/(Q6*40)*1000000000 -> 49.913793 | R19: =R16/(R6*40)*1000000000 -> 99.295775 | S19: =S16/(S6*40)*1000000000 -> 33.586957 | T19: =T16/(T6*40)*1000000000 -> 21.354167 | U19: =U16/(U6*40)*1000000000 -> 49.315068 | V19: =V16/(V6*40)*1000000000 -> 7.3723404 | W19: =W16/(W6*40)*1000000000 -> 23.716632 | X19: =X16/(X6*40)*1000000000 -> 3.8671875
C20: ADN/Videodrop après (1E-9 ng.mL/parts) | D20: =D16/(D11*0.2)*1000000000 -> 52.079566 | E20: =E16/(E11*0.2)*1000000000 -> 119.14894 | F20: =F16/(F11*0.2)*1000000000 -> 59.15493 | G20: =G16/(G11*0.2)*1000000000 -> 231.57895 | H20: =H16/(H11*0.2)*1000000000 -> 123.69942 | I20: =I16/(I11*0.2)*1000000000 -> 865.30612 | J20: =J16/(J11*0.2)*1000000000 -> 45.964912 | K20: =K16/(K11*0.2)*1000000000 -> 114.70588 | L20: =L16/(L11*0.2)*1000000000 -> 6.7874016 | O20: ADN/Videodrop après (1E-9 ng.mL/parts) | P20: =P16/(P11*0.2)*1000000000 -> 37.246753 | Q20: =Q16/(Q11*0.2)*1000000000 -> 110.28571 | R20: =R16/(R11*0.2)*1000000000 -> 146.36678 | S20: =S16/(S11*0.2)*1000000000 -> 53.73913 | T20: =T16/(T11*0.2)*1000000000 -> 28.082192 | U20: =U16/(U11*0.2)*1000000000 -> 186.2069 | V20: =V16/(V11*0.2)*1000000000 -> 49.148936 | W20: =W16/(W11*0.2)*1000000000 -> 172.38806 | X20: =X16/(X11*0.2)*1000000000 -> 23.571429
C21: Remarque | D21: Videodrop après D=14 (bien) | G21: Videodrop après D=491 (trop dilué) | O21: Remarque | P21: Videodrop après D=14 (bien)
B22: g2 | C22: Cytometry (parts/mL) | G22: 1.9414034e+08 | H22: 1.9141016e+08 | I22: 89152657 | J22: 492635.73 | K22: 388922.94 | L22: 243725.04 | N22: g2 | O22: Cytometry (parts/mL) | P22: 46743511 | Q22: 48606320 | R22: 44274206 | S22: 1.3516005e+08 | T22: 1.7290653e+08 | U22: 1.8868118e+08 | V22: 466069.14 | W22: 466069.14 | X22: 460947.5
C23: Videodrop avant (parts/mL) | G23: 215000000 | H23: 237000000 | I23: 119000000 | J23: 698000000 | K23: 654000000 | L23: 520000000 | O23: Videodrop avant (parts/mL) | P23: 53100000 | Q23: 4860000 | R23: 73900000 | S23: 109000000 | T23: 129000000 | U23: 173000000 | V23: 90300000 | W23: 108000000 | X23: 41100000
C24: Videodrop avant/cyto (%) | G24: =G23/G22*100 -> 110.74463 | H24: =H23/H22*100 -> 123.81788 | I24: =I23/I22*100 -> 133.47892 | J24: =J23/J22*100 -> 141686.84 | K24: =K23/K22*100 -> 168156.7 | L24: =L23/L22*100 -> 213355.18 | O24: Videodrop avant/cyto (%) | P24: =P23/P22*100 -> 113.59865 | Q24: =Q23/Q22*100 -> 9.9986997 | R24: =R23/R22*100 -> 166.91434 | S24: =S23/S22*100 -> 80.645131 | T24: =T23/T22*100 -> 74.606783 | U24: =U23/U22*100 -> 91.689061 | V24: =V23/V22*100 -> 19374.808 | W24: =W23/W22*100 -> 23172.528 | X24: =X23/X22*100 -> 8916.4167
C25: Nouveau cyto | J25: 340000 | K25: 206000
C26: nouveau cyto/cyto | J26: =J25/J22*100 -> 69.016513 | K26: =K25/K22*100 -> 52.966791
C27: decay (d-1) | J27: =(log(J22)-log(J25))/719 -> 0.00022398747 | K27: =(log(K22)-log(K25))/719 -> 0.00038386139
C28: Videodrop après (parts/mL) | G28: 11200000000 | H28: 9280000000 | I28: 5920000000 | J28: 105000000000 | K28: 87500000000 | L28: 64200000000 | O28: Videodrop après (parts/mL) | P28: 3850000000 | Q28: 849000000 | R28: 4240000000 | S28: 1700000000 | T28: 8050000000 | U28: 9760000000 | V28: 2990000000 | W28: 5540000000 | X28: 5570000000
C29: Videodrop après/cyto (%) | G29: =(G28*0.2)/(G22*40)*100 -> 28.845113 | H29: =(H28*0.2)/(H22*40)*100 -> 24.241138 | I29: =(I28*0.2)/(I22*40)*100 -> 33.201478 | J29: =(J28*0.2)/(J22*40)*100 -> 106569.62 | K29: =(K28*0.2)/(K22*40)*100 -> 112490.15 | L29: =(L28*0.2)/(L22*40)*100 -> 131705.79 | O29: Videodrop après/cyto (%) | P29: =(P28*0.2)/(P22*40)*100 -> 41.182186 | Q29: =(Q28*0.2)/(Q22*40)*100 -> 8.7334321 | R29: =(R28*0.2)/(R22*40)*100 -> 47.883411 | S29: =(S28*0.2)/(S22*40)*100 -> 6.2888405 | T29: =(T28*0.2)/(T22*40)*100 -> 23.278473 | U29: =(U28*0.2)/(U22*40)*100 -> 25.863735 | V29: =(V28*0.2)/(V22*40)*100 -> 3207.6786 | W29: =(W28*0.2)/(W22*40)*100 -> 5943.3242 | X29: =(X28*0.2)/(X22*40)*100 -> 6041.9028
C30: Videodrop après/avant (%) | G30: =(G28*0.2)/(G23*40)*100 -> 26.046512 | H30: =(H28*0.2)/(H23*40)*100 -> 19.578059 | I30: =(I28*0.2)/(I23*40)*100 -> 24.87395 | J30: =(J28*0.2)/(J23*40)*100 -> 75.2149 | K30: =(K28*0.2)/(K23*40)*100 -> 66.896024 | L30: =(L28*0.2)/(L23*40)*100 -> 61.730769 | O30: Videodrop après/avant (%) | P30: =(P28*0.2)/(P23*40)*100 -> 36.252354 | Q30: =(Q28*0.2)/(Q23*40)*100 -> 87.345679 | R30: =(R28*0.2)/(R23*40)*100 -> 28.687415 | S30: =(S28*0.2)/(S23*40)*100 -> 7.7981651 | T30: =(T28*0.2)/(T23*40)*100 -> 31.20155 | U30: =(U28*0.2)/(U23*40)*100 -> 28.208092 | V30: =(V28*0.2)/(V23*40)*100 -> 16.555925 | W30: =(W28*0.2)/(W23*40)*100 -> 25.648148 | X30: =(X28*0.2)/(X23*40)*100 -> 67.761557
C31: Volume (μL) | G31: 40 | H31: 40 | I31: 40 | J31: 40 | K31: 40 | L31: 40 | O31: Volume (μL) | P31: 30 | Q31: 30 | R31: 30 | S31: 30 | T31: 30 | U31: 30 | V31: 30 | W31: 30 | X31: 30
C32: Qubit (ng/μL) | G32: 12.2 | H32: 14.1 | I32: 6.46 | J32: 1.66 | K32: 12.9 | L32: 0.482 | O32: Qubit (ng/μL) | P32: 2.14 | Q32: 6.62 | R32: 1.45 | S32: 12.4 | T32: 8.44 | U32: 45.6 | V32: 6.92 | W32: 3.02 | X32: 6.54
C33: Masse ADN (ng) | G33: =G32*G31 -> 488 | H33: =H32*H31 -> 564 | I33: =I32*I31 -> 258.4 | J33: =J32*J31 -> 66.4 | K33: =K32*K31 -> 516 | L33: =L32*L31 -> 19.28 | O33: Masse ADN (ng) | P33: =P32*P31 -> 64.2 | Q33: =Q32*Q31 -> 198.6 | R33: =R32*R31 -> 43.5 | S33: =S32*S31 -> 372 | T33: =T32*T31 -> 253.2 | U33: =U32*U31 -> 1368 | V33: =V32*V31 -> 207.6 | W33: =W32*W31 -> 90.6 | X33: =X32*X31 -> 196.2
G34: =G33/G28 -> 4.3571429e-08 | H34: =H33/H28 -> 6.0775862e-08 | I34: =I33/I28 -> 4.3648649e-08 | J34: =J33/J28 -> 6.3238095e-10 | K34: =K33/K28 -> 5.8971429e-09 | L34: =L33/L28 -> 3.0031153e-10 | P34: =P33/P23 -> 1.2090395e-06 | Q34: =Q33/Q23 -> 4.0864198e-05 | R34: =R33/R23 -> 5.8863329e-07 | S34: =S33/S23 -> 3.412844e-06 | T34: =T33/T23 -> 1.9627907e-06 | U34: =U33/U23 -> 7.9075145e-06 | V34: =V33/V23 -> 2.2990033e-06 | W34: =W33/W23 -> 8.3888889e-07 | X34: =X33/X23 -> 4.7737226e-06
C35: ADN/cyto (1E-9 ng.mL/parts) | G35: =G33/(G22*40)*1000000000 -> 62.84114 | H35: =H33/(H22*40)*1000000000 -> 73.663802 | I35: =I33/(I22*40)*1000000000 -> 72.459983 | J35: =J33/(J22*40)*1000000000 -> 3369.6297 | K35: =K33/(K22*40)*1000000000 -> 33168.524 | L35: =L33/(L22*40)*1000000000 -> 1977.6384 | O35: ADN/cyto (1E-9 ng.mL/parts) | P35: =P33/(P22*40)*1000000000 -> 34.336317 | Q35: =Q33/(Q22*40)*1000000000 -> 102.14721 | R35: =R33/(R22*40)*1000000000 -> 24.562834 | S35: =S33/(S22*40)*1000000000 -> 68.807313 | T35: =T33/(T22*40)*1000000000 -> 36.609375 | U35: =U33/(U22*40)*1000000000 -> 181.25814 | V35: =V33/(V22*40)*1000000000 -> 11135.687 | W35: =W33/(W22*40)*1000000000 -> 4859.794 | X35: =X33/(X22*40)*1000000000 -> 10641.125
C36: ADN/Videodrop avant (1E-9 ng.mL/parts) | G36: =G33/(G23*40)*1000000000 -> 56.744186 | H36: =H33/(H23*40)*1000000000 -> 59.493671 | I36: =I33/(I23*40)*1000000000 -> 54.285714 | J36: =J33/(J23*40)*1000000000 -> 2.3782235 | K36: =K33/(K23*40)*1000000000 -> 19.724771 | L36: =L33/(L23*40)*1000000000 -> 0.92692308 | O36: ADN/Videodrop avant (1E-9 ng.mL/parts) | P36: =P33/(P23*40)*1000000000 -> 30.225989 | Q36: =Q33/(Q23*40)*1000000000 -> 1021.6049 | R36: =R33/(R23*40)*1000000000 -> 14.715832 | S36: =S33/(S23*40)*1000000000 -> 85.321101 | T36: =T33/(T23*40)*1000000000 -> 49.069767 | U36: =U33/(U23*40)*1000000000 -> 197.68786 | V36: =V33/(V23*40)*1000000000 -> 57.475083 | W36: =W33/(W23*40)*1000000000 -> 20.972222 | X36: =X33/(X23*40)*1000000000 -> 119.34307
C37: ADN/Videodrop après (1E-9 ng.mL/parts) | G37: =G33/(G28*0.2)*1000000000 -> 217.85714 | H37: =H33/(H28*0.2)*1000000000 -> 303.87931 | I37: =I33/(I28*0.2)*1000000000 -> 218.24324 | J37: =J33/(J28*0.2)*1000000000 -> 3.1619048 | K37: =K33/(K28*0.2)*1000000000 -> 29.485714 | L37: =L33/(L28*0.2)*1000000000 -> 1.5015576 | O37: ADN/Videodrop après (1E-9 ng.mL/parts) | P37: =P33/(P28*0.2)*1000000000 -> 83.376623 | Q37: =Q33/(Q28*0.2)*1000000000 -> 1169.6113 | R37: =R33/(R28*0.2)*1000000000 -> 51.29717 | S37: =S33/(S28*0.2)*1000000000 -> 1094.1176 | T37: =T33/(T28*0.2)*1000000000 -> 157.26708 | U37: =U33/(U28*0.2)*1000000000 -> 700.81967 | V37: =V33/(V28*0.2)*1000000000 -> 347.15719 | W37: =W33/(W28*0.2)*1000000000 -> 81.768953 | X37: =X33/(X28*0.2)*1000000000 -> 176.12208
C38: Remarque | H38: Contaminé par 20A g2 | J38: Double CTAB -> 2 tubes jusque AcNHI4 | O38: Remarque | P38: Videodrop après D=14 (bien)
G39: Videodrop après D=491 (trop dilué)
B40: g3 | C40: Cytometry (parts/mL) | G40: 2.7284386e+08 | H40: 1.8400145e+08 | I40: 1.7634455e+08 | J40: 2187931 | K40: 923793.1 | L40: 826551.72 | N40: g3 | O40: Cytometry (parts/mL) | S40: 1.6799939e+08 | T40: 1.7995602e+08 | U40: 1.3693813e+08
C41: Videodrop avant (parts/mL) | G41: 388000000 | H41: 282000000 | I41: 260000000 | J41: 140000000 | L41: 81000000 | O41: Videodrop avant (parts/mL) | S41: 201000000 | T41: 106000000 | U41: 197000000
...

Sheet Test 20 26 no virus Videodrop
A1: Mic_no_V_20 filt 1.2um | B1: Mic_no_V_26 filt 1.2um | C1: dans dossier test
A2: 98 | B2: 263
A3: 11800000 | B3: 72700000
A4: 2 particules entre 200 et 300 | B4: Pas mal de gros trucs -> on va filtrer 0,45
A5: 7 particules trackées | B5: plus de particules -> vésicules ?
A6: 1 particule au dessus de 400

Sheet Boxplot ratio Videodrop
A1: data15 | B1: data20 | C1: data26
A2: 57.724426 | B2: 27.737226 | C2: 59.375
A3: 75 | B3: 18.92779 | C3: 68.686869
A4: 43.351425 | B4: 20.360111 | C4: 43.944637
A5: 26.47868 | B5: 62.5 | C5: 15
A6: 45.258621 | B6: 76.041667 | C6: 13.7577
A7: 67.840376 | B7: 26.484018 | C7: 16.40625
A8: 36.252354 | B8: 26.046512 | C8: 75.2149
A9: 87.345679 | B9: 19.578059 | C9: 66.896024
A10: 28.687415 | B10: 24.87395 | C10: 61.730769
B11: 7.7981651 | C11: 16.555925
B12: 31.20155 | C12: 25.648148
B13: 28.208092 | C13: 67.761557
B14: 31.701031 | C14: 73.928571
B15: 35.992908 | C15: 85.802469
B16: 80 | C16: 122.5
B17: 14.253731 | C17: 133.5443
B18: 31.603774 | C18: 81.368821
B19: 13.147208 | C19: 104.35435
B20: 199.11504 | C20: 52.265372
B21: 65.755208 | C21: 35.128205
B22: 41.331803
B23: 14.357143
B24: 14.757709

Sheet Boxplot ratio DNA
A1: data15 | B1: data20 | C1: data26
A2: 1.0415913e-08 | B2: 4.6315789e-08 | C2: 9.1929825e-09
A3: 2.3829787e-08 | B3: 2.4739884e-08 | C3: 2.2941176e-08
A4: 1.1830986e-08 | B4: 1.7306122e-07 | C4: 1.3574803e-09
A5: 7.4493506e-09 | B5: 1.0747826e-08 | C5: 9.8297872e-09
A6: 2.2057143e-08 | B6: 5.6164384e-09 | C6: 3.4477612e-08
A7: 2.9273356e-08 | B7: 3.7241379e-08 | C7: 4.7142857e-09
A8: 1.2090395e-06 | B8: 4.3571429e-08 | C8: 6.3238095e-10
A9: 4.0864198e-05 | B9: 6.0775862e-08 | C9: 5.8971429e-09
A10: 5.8863329e-07 | B10: 4.3648649e-08 | C10: 3.0031153e-10
B11: 3.412844e-06 | C11: 2.2990033e-06
B12: 1.9627907e-06 | C12: 8.3888889e-07
B13: 7.9075145e-06 | C13: 4.7737226e-06
B14: 4.1300813e-08 | C14: 1.426087e-08
B15: 6.5418719e-08 | C15: 1.098966e-07
B16: 3.1153846e-08 | C16: 3.2517986e-08
B17: 1.5373134e-07 | C17: 1.1791383e-08
B18: 5.2075472e-06 | C18: 7.8104265e-09
B19: 1.3583756e-06 | C19: 1.317757e-08
B20: 1.277037e-08 | C20: 4.048048e-07
B21: 1.8851485e-08 | C21: 1.1210356e-07
B22: 1.9399333e-08 | C22: 3.0564103e-06
B23: 3.26062e-06
B24: 7.1428571e-06
B25: 4.5374449e-06

Sheet Boxplot number of particles V2
A1: data15 | B1: data20 | C1: data26
A2: 114 | B2: 23 | C2: 256
A3: 183 | B3: 15 | C3: 266
A4: 126 | B4: 15 | C4: 247
A5: 83 | B5: 7 | C5: 110
A6: 110 | B6: 8 | C6: 102
A7: 119 | B7: 12 | C7: 47
A8: 22 | B8: 22 | C8: 17
A9: 14 | B9: 18 | C9: 7
A10: 83 | B10: 38 | C10: 11
B11: 129 | C11: 40
B12: 59 | C12: 35
B13: 80 | C13: 35
B14: 70 | C14: 136
B15: 25 | C15: 32
B16: 28 | C16: 18
B17: 301 | C17: 309
B18: 313 | C18: 301
B19: 212 | C19: 307
B20: 37 | C20: 58
B21: 154 | C21: 105
B22: 197 | C22: 121
B23: 114
B24: 135
B25: 9

Sheet Boxplot number of particles V1
A1: data15 | B1: data20 | C1: data26
A2: 24 | B2: 180 | C2: 323
A3: 28 | B3: 229 | C3: 345
A4: 18 | B4: 180 | C4: 323
A5: 18 | B5: 101 | C5: 312
A6: 15 | B6: 105 | C6: 318
A7: 11 | B7: 54 | C7: 281
A8: =(17+4)/2 -> 10.5 | B8: 181 | C8: 56
A9: =(7+2)/2 -> 4.5 | B9: 139 | C9: 38
A10: 19 | B10: 136 | C10: 81
B11: 172 | C11: 78
B12: 156 | C12: 113
B13: 313 | C13: 308
B14: 304 | C14: 132
B15: 305 | C15: 82
B16: 55 | C16: 159
B17: 40 | C17: 153
B18: 67 | C18: 151
B19: 39 | C19: 29
B20: 37 | C20: 26
B21: 47 | C21: =(11+12)/2 -> 11.5
B22: 59
B23: 32
B24: 47

Sheet Boxplot median diameter V2
A1: data15 | B1: data20 | C1: data26
A2: 308 | B2: 237 | C2: 264
A3: 277 | B3: 408 | C3: 250
A4: 301 | B4: 204 | C4: 225
A5: 288 | B5: 219 | C5: 196
A6: 251 | B6: 239 | C6: 212
A7: 259 | B7: 358 | C7: 237
A8: 476 | B8: 253 | C8: 247
A9: 408 | B9: 275 | C9: 362
A10: 329 | B10: 287 | C10: 167
B11: 224 | C11: 225
B12: 261 | C12: 204
B13: 228 | C13: 286
B14: 209 | C14: 198
B15: 164 | C15: 239
B16: 198 | C16: 195
B17: 340 | C17: 261
B18: 397 | C18: 318
B19: 285 | C19: 248
B20: 169 | C20: 231
B21: 353 | C21: 291
B22: 296 | C22: 287
B23: 313
B24: 335
B25: 314

Sheet Boxplot median diameter V1
A1: data15 | B1: data20 | C1: data26
A2: 223 | B2: 187 | C2: 239
A3: 231 | B3: 182 | C3: 236
A4: 264 | B4: 202 | C4: 247
A5: 215 | B5: 194 | C5: 202
A6: 225 | B6: 179 | C6: 197
A7: 292 | B7: 205 | C7: 194
A8: =(193+195)/2 -> 194 | B8: 176 | C8: 236
A9: =(660+176)/2 -> 418 | B9: 181 | C9: 191
A10: 230 | B10: 210 | C10: 244
B11: 174 | C11: 190
B12: 180 | C12: 223
B13: 179 | C13: 211
B14: 178 | C14: 203
B15: 183 | C15: 229
B16: 20 | C16: 213
B17: 187 | C17: 234
B18: 173 | C18: 213
B19: 183 | C19: 337
B20: 191 | C20: 273
B21: 185 | C21: =(450+251)/2 -> 350.5
B22: 201
B23: 254
B24: 298

Sheet Size
B1: 20 | F1: 26
B2: a | C2: b | D2: c | E2: moyenne | F2: a | G2: b | H2: c | I2: moyenne
A3: g1 | B3: 187 | C3: 182 | D3: 202 | E3: =AVERAGE(B3:D3) -> 190.33333 | F3: 239 | G3: 236 | H3: 247 | I3: =AVERAGE(F3:H3) -> 240.66667
A4: g2 | B4: 194 | C4: 179 | D4: 205 | E4: =AVERAGE(B4:D4) -> 192.66667 | F4: 202 | G4: 197 | H4: 194 | I4: =AVERAGE(F4:H4) -> 197.66667
A5: g3 | B5: 176 | C5: 181 | D5: 210 | E5: =AVERAGE(B5:D5) -> 189 | F5: 236 | H5: 190 | I5: =AVERAGE(F5:H5) -> 213
A6: g4 | B6: 174 | C6: 180 | E6: =AVERAGE(B6:D6) -> 177 | F6: 244 | G6: 190 | H6: 223 | I6: =AVERAGE(F6:H6) -> 219
A7: g5 | B7: 179 | C7: 178 | D7: 183 | E7: =AVERAGE(B7:D7) -> 180 | F7: 211 | G7: 203 | H7: 229 | I7: =AVERAGE(F7:H7) -> 214.33333
K13: Rouge = 26°C
K14: Bleu = 20°C
K15: Abscisse = générations

Sheet Boxplot decay 20 vs 26
A1: data20 | B1: data26
A2: 0.00051023454 | B2: 0.0016978616
A3: 0.00041602125 | B3: 0.00022398747
A4: 0.00041214248 | B4: 0.00038386139
A5: 0.00040840554 | B5: 0.00084984171
A6: 0.00050205989 | B6: 0.00022223469
A7: 0.00052538354

Sheet Cyto 1 vs Cyto 2
A1: Cyto 1 | B1: Cyto 2
A2: 223000000 | B2: 118000000
A3: 341000000 | B3: 179000000
A4: 429000000 | B4: 186000000
A5: 800000000 | B5: 356000000
A6: 1270000000 | B6: 584000000
A7: 337000000 | B7: 176000000
A8: 794000 | B8: 552000
A9: 4960000 | B9: 289000
A10: 1140000 | B10: 284000
A11: 389000 | B11: 206000
A12: 493000 | B12: 340000

Sheet Feuille 5
A1: coevo 15 C | B1: coevo 15 V | C1: coevo 20 C | D1: coevo 20 V | E1: coevo 26 C | F1: coevo 26 V | G1: virus 15 C | H1: virus 15 V | I1: virus 20 C | J1: virus 20 V | K1: virus 26 C | L1: virus 26 V
A2: 1000000 | B2: 1000000 | C2: 1000000 | D2: 1000000 | E2: 1000000 | F2: 1000000 | G2: 1000000 | H2: 1000000 | I2: 1000000 | J2: 1000000 | K2: 1000000 | L2: 1000000
A3: =AVERAGE(Virus!D5:F5) -> 57797623 | B3: =AVERAGE(Virus!D6:F6) -> 59333333 | C3: =AVERAGE(Virus!G5:I5) -> 4.6773103e+08 | D3: =AVERAGE(Virus!G6:I6) -> 4.0966667e+08 | E3: =AVERAGE(Virus!J5:L5) -> 4370308.1 | F3: =AVERAGE(Virus!J6:L6) -> 2263333333 | G3: =AVERAGE(Virus!P5:R5) -> 57280563 | H3: =AVERAGE(Virus!P6:R6) -> 57766667 | I3: =AVERAGE(Virus!S5:U5) -> 3.4174732e+08 | J3: =AVERAGE(Virus!S6:U6) -> 1.8233333e+08 | K3: =AVERAGE(Virus!V5:X5) -> 4310922.9 | L3: =AVERAGE(Virus!V6:X6) -> 4.8966667e+08
C4: =AVERAGE(Virus!G22:I22) -> 1.5823438e+08 | D4: =AVERAGE(Virus!G23:I23) -> 1.9033333e+08 | E4: =AVERAGE(Virus!J22:L22) -> 375094.57 | F4: =AVERAGE(Virus!J23:L23) -> 624000000 | G4: =AVERAGE(Virus!P22:R22) -> 46541346 | H4: =AVERAGE(Virus!P23:R23) -> 43953333 | I4: =AVERAGE(Virus!S22:U22) -> 1.6558259e+08 | J4: =AVERAGE(Virus!S23:U23) -> 137000000 | K4: =AVERAGE(Virus!V22:X22) -> 464361.93 | L4: =AVERAGE(Virus!V23:X23) -> 79800000
C5: =AVERAGE(Virus!G40:I40) -> 211063290 | D5: =AVERAGE(Virus!G41:I41) -> 310000000 | E5: =AVERAGE(Virus!J40:L40) -> 1312758.6 | F5: =AVERAGE(Virus!J41:L41) -> 110500000 | I5: =AVERAGE(Virus!S40:U40) -> 1.6163118e+08 | J5: =AVERAGE(Virus!S41:U41) -> 168000000
C6: =AVERAGE(Virus!G55:I55) -> 3.0056353e+08 | D6: =AVERAGE(Virus!G56:I56) -> 361500000 | E6: =AVERAGE(Virus!J55:L55) -> 1042430.8 | F6: =AVERAGE(Virus!J56:L56) -> 2.0033333e+08
C7: =AVERAGE(Virus!G72:I72) -> 1040371646 | D7: =AVERAGE(Virus!G73:I73) -> 8.2633333e+08 | E7: =AVERAGE(Virus!J72:L72) -> 876965.63 | F7: =AVERAGE(Virus!J73:L73) -> 390000000

Sheet Compare cyto videodrop
A1: cyto 15 | B1: cyto 20 | C1: cyto 26 | D1: videodrop 15 | E1: videodrop 20 | F1: videodrop 26
A2: 53285004 | B2: 4.7166931e+08 | C2: 3045267.9 | D2: 47900000 | E2: 411000000 | F2: 1920000000
A3: 53783197 | B3: 5.0268931e+08 | C3: 5108378.8 | D3: 56400000 | E3: 457000000 | F3: 1980000000
A4: 66324667 | B4: 4.2883448e+08 | C4: 4957277.7 | D4: 73700000 | E4: 361000000 | F4: 2890000000
A5: 48267887 | B5: 1.9414034e+08 | C5: 492635.73 | D5: 72700000 | E5: 215000000 | F5: 698000000
A6: 62537958 | B6: 1.9141016e+08 | C6: 388922.94 | D6: 58000000 | E6: 237000000 | F6: 654000000
A7: 61035845 | B7: 89152657 | C7: 243725.04 | D7: 42600000 | E7: 119000000 | F7: 520000000
B8: 2.7284386e+08 | C8: 2187931 | E8: 388000000 | F8: 140000000
B9: 1.8400145e+08 | C9: 923793.1 | E9: 282000000 | F9: 81000000
B10: 1.7634455e+08 | C10: 826551.72 | E10: 260000000 | F10: 180000000
B11: 3.3728039e+08 | C11: 1191349.5 | E11: 339000000 | F11: 158000000
B12: 3.4095556e+08 | C12: 1141710 | E12: 384000000 | F12: 263000000
B13: 2.2345464e+08 | C13: 794233.03 | E13: 871000000 | F13: 666000000
B14: 1.2655838e+09 | C14: 694953.9 | E14: 700000000 | F14: 309000000
B15: 7.9970827e+08 | C15: 893512.15 | E15: 908000000 | F15: 195000000
B16: 1.0558229e+09 | C16: 1042430.8 | E16: 184000000 | F16: 470000000
B17: 3.3346901e+08 | C17: 4141307.4 | E17: 144000000 | F17: 487000000
B18: 4.0316704e+08 | C18: 3758412.8 | E18: 219000000 | F18: 512000000
B19: 2.8860592e+08 | C19: 5033048.7 | E19: 109000000 | F19: 90300000
... B21: 1.7290653e+08 | C21: 466069.14 | E21: 173000000 | F21: 41100000
B22: 1.8868118e+08 | C22: 460947.5 | E22: 201000000
B23: 1.6799939e+08 | E23: 106000000
B24: 1.7995602e+08 | E24: 197000000
B25: 1.3693813e+08
